I'm sorry, but an uncaught exception occurred.

While running game code:
  File "game/script.rpy", line 472, in script
    show Hitomi m_09
Exception: When showing Hitomi, m_09 is not a known attribute.

-- Full Traceback ------------------------------------------------------------

Full traceback:
  File "game/script.rpy", line 472, in script
    show Hitomi m_09
  File "/Users/taeyunroh/Documents/renpy-8.1.1-sdk/renpy/ast.py", line 1428, in execute
    show_imspec(self.imspec, atl=getattr(self, "atl", None))
  File "/Users/taeyunroh/Documents/renpy-8.1.1-sdk/renpy/ast.py", line 1391, in show_imspec
    renpy.config.show(name,
  File "/Users/taeyunroh/Documents/renpy-8.1.1-sdk/renpy/exports.py", line 733, in show
    if not base.find_target() and renpy.config.missing_show:
  File "/Users/taeyunroh/Documents/renpy-8.1.1-sdk/renpy/display/image.py", line 421, in find_target
    self.target = target._duplicate(a)
  File "/Users/taeyunroh/Documents/renpy-8.1.1-sdk/renpy/gl2/live2d.py", line 627, in _duplicate
    raise Exception("When showing {}, {} is not a known attribute.".format(" ".join(args.name), i))
Exception: When showing Hitomi, m_09 is not a known attribute.

macOS-13.2.1-arm64-arm-64bit arm64
Ren'Py 8.1.1.23060707
kaistmossolescape 1.0
Mon Jul 17 21:55:39 2023
